<robot name="j2n4s300" version="1.0">
    <link name="link_base">
        <inertial>
            <mass value="0.46784" />
            <origin xyz="0 0 0.1255" rpy="0 0 0" />
            <inertia ixx="0.0009512746666666667" ixy="0.0" ixz="0.0" iyy="0.0009512746666666667"
                iyz="0.0" izz="0.000374272" />
        </inertial>

        <visual>
            <origin xyz="0 0 0" rpy="0 0 0" />
            <geometry>
                <mesh filename="package://kinova_description/meshes/base.dae" />
            </geometry>
        </visual>
        <collision>
            <origin xyz="0 0 0" rpy="0 0 0" />
            <geometry>
                <mesh filename="package://kinova_description/meshes/base.STL" />
            </geometry>
        </collision>
    </link>

    <link name="link_1">
        <inertial>
            <mass value="0.7477" />
            <origin xyz="0 -0.002 -0.0605" />
            <inertia ixx="0.0015203233333333337" ixy="0.0" ixz="0.0" iyy="0.0015203233333333337"
                iyz="0.0" izz="0.00059816" />
        </inertial>

        <visual>
            <origin xyz="0 0 0" rpy="0 0 0" />
            <geometry>
                <mesh filename="package://kinova_description/meshes/shoulder.dae" />
            </geometry>
        </visual>

        <collision>
            <origin xyz="0 0 0" rpy="0 0 0" />
            <geometry>
                <mesh filename="package://kinova_description/meshes/shoulder.STL" />
            </geometry>
        </collision>
    </link>

    <joint name="joint_1" type="revolute">
        <origin
            xyz="0 0 0.15675" rpy="0 3.14159 0" />
        <parent
            link="link_base" />
        <child
            link="link_1" />
        <axis
            xyz="0 0 1" />
        <limit
            lower="-6.2832"
            upper="6.2832"
            velocity="0.62832"
            effort="1000" />
    </joint>


    <link name="link_2">
        <inertial>
            <mass value="0.99" />
            <origin xyz="0 -0.2065 -0.01" />
            <inertia ixx="0.01050225" ixy="0.0" ixz="0.0" iyy="0.01050225" iyz="0.0" izz="0.000792" />
        </inertial>

        <visual>
            <origin xyz="0 0 0" rpy="0 0 0" />
            <geometry>
                <mesh filename="package://kinova_description/meshes/arm.dae" />
            </geometry>
        </visual>

        <collision>
            <origin xyz="0 0 0" rpy="0 0 0" />
            <geometry>
                <mesh filename="package://kinova_description/meshes/arm.STL" />
            </geometry>
        </collision>
    </link>

    <joint name="joint_2" type="revolute">
        <origin
            xyz="0 0.0016 -0.11875" rpy="1.5708 0 0" />
        <parent
            link="link_1" />
        <child
            link="link_2" />
        <axis
            xyz="0 0 1" />
        <limit
            lower="-2.3213"
            upper="2.3213"
            velocity="0.62832"
            effort="1000" />
    </joint>

    <link name="link_3">
        <inertial>
            <mass value="0.6763" />
            <origin xyz="0 0.081 -0.0086" />
            <inertia ixx="0.0014202300000000002" ixy="0.0" ixz="0.0" iyy="0.0014202300000000002"
                iyz="0.0" izz="0.000304335" />
        </inertial>

        <visual>
            <origin xyz="0 0 0" rpy="0 0 0" />
            <geometry>
                <mesh filename="package://kinova_description/meshes/forearm.dae" />
            </geometry>
        </visual>

        <collision>
            <origin xyz="0 0 0" rpy="0 0 0" />
            <geometry>
                <mesh filename="package://kinova_description/meshes/forearm.STL" />
            </geometry>
        </collision>
    </link>

    <joint name="joint_3" type="revolute">
        <origin
            xyz="0 -0.410 0" rpy="3.1416 0 0" />
        <parent
            link="link_2" />
        <child
            link="link_3" />
        <axis
            xyz="0 0 1" />
        <limit
            lower="-2.809"
            upper="2.809"
            velocity="0.62832"
            effort="1000" />
    </joint>

    <link name="link_4">
        <inertial>
            <mass value="0.426367" />
            <origin xyz="0 -0.037 -0.0642" />
            <inertia ixx="7.735000000000001e-05" ixy="0.0" ixz="0.0" iyy="7.735000000000001e-05"
                iyz="0.0" izz="0.0001428" />
        </inertial>

        <visual>
            <origin xyz="0 0 0" rpy="0 0 0" />
            <geometry>
                <mesh filename="package://kinova_description/meshes/wrist.dae" />
            </geometry>
        </visual>

        <collision>
            <origin xyz="0 0 0" rpy="0 0 0" />
            <geometry>
                <mesh filename="package://kinova_description/meshes/wrist.STL" />
            </geometry>
        </collision>
    </link>

    <joint name="joint_4" type="revolute">
        <origin
            xyz="0 0.2073 -0.0114" rpy="-1.5708 0 3.1416" />
        <parent
            link="link_3" />
        <child
            link="link_4" />
        <axis
            xyz="0 0 1" />
        <limit
            lower="-6.2832"
            upper="6.2832"
            velocity="0.8377"
            effort="1000" />
    </joint>

    <link name="end_effector">
    </link>

    <joint name="EndEffector" type="fixed">
        <origin xyz="0 0 0" rpy="3.1419 0 1.5708" />
        <parent link="link_4" />
        <child link="end_effector" />
        <axis xyz="0 0 0" />
    </joint>

</robot>